package net.minecraft.world.level.levelgen.structure.structures;

import net.minecraft.core.BlockPos;
import net.minecraft.core.Direction;
import net.minecraft.nbt.CompoundTag;
import net.minecraft.util.RandomSource;
import net.minecraft.world.level.ChunkPos;
import net.minecraft.world.level.StructureManager;
import net.minecraft.world.level.WorldGenLevel;
import net.minecraft.world.level.block.Blocks;
import net.minecraft.world.level.block.StairBlock;
import net.minecraft.world.level.block.state.BlockState;
import net.minecraft.world.level.chunk.ChunkGenerator;
import net.minecraft.world.level.levelgen.structure.BoundingBox;
import net.minecraft.world.level.levelgen.structure.ScatteredFeaturePiece;
import net.minecraft.world.level.levelgen.structure.pieces.StructurePieceSerializationContext;
import net.minecraft.world.level.levelgen.structure.pieces.StructurePieceType;
import net.minecraft.world.level.storage.loot.BuiltInLootTables;

public class DesertPyramidPiece extends ScatteredFeaturePiece {
   public static final int WIDTH = 21;
   public static final int DEPTH = 21;
   private final boolean[] hasPlacedChest = new boolean[4];

   public DesertPyramidPiece(RandomSource var1, int var2, int var3) {
      super(StructurePieceType.DESERT_PYRAMID_PIECE, var2, 64, var3, 21, 15, 21, getRandomHorizontalDirection(var1));
   }

   public DesertPyramidPiece(CompoundTag var1) {
      super(StructurePieceType.DESERT_PYRAMID_PIECE, var1);
      this.hasPlacedChest[0] = var1.getBoolean("hasPlacedChest0");
      this.hasPlacedChest[1] = var1.getBoolean("hasPlacedChest1");
      this.hasPlacedChest[2] = var1.getBoolean("hasPlacedChest2");
      this.hasPlacedChest[3] = var1.getBoolean("hasPlacedChest3");
   }

   @Override
   protected void addAdditionalSaveData(StructurePieceSerializationContext var1, CompoundTag var2) {
      super.addAdditionalSaveData(var1, var2);
      var2.putBoolean("hasPlacedChest0", this.hasPlacedChest[0]);
      var2.putBoolean("hasPlacedChest1", this.hasPlacedChest[1]);
      var2.putBoolean("hasPlacedChest2", this.hasPlacedChest[2]);
      var2.putBoolean("hasPlacedChest3", this.hasPlacedChest[3]);
   }

   @Override
   public void postProcess(WorldGenLevel var1, StructureManager var2, ChunkGenerator var3, RandomSource var4, BoundingBox var5, ChunkPos var6, BlockPos var7) {
      if (this.updateHeightPositionToLowestGroundHeight(var1, -var4.nextInt(3))) {
         this.generateBox(
            var1, var5, 0, -4, 0, this.width - 1, 0, this.depth - 1, Blocks.SANDSTONE.defaultBlockState(), Blocks.SANDSTONE.defaultBlockState(), false
         );

         for(int var8 = 1; var8 <= 9; ++var8) {
            this.generateBox(
               var1,
               var5,
               var8,
               var8,
               var8,
               this.width - 1 - var8,
               var8,
               this.depth - 1 - var8,
               Blocks.SANDSTONE.defaultBlockState(),
               Blocks.SANDSTONE.defaultBlockState(),
               false
            );
            this.generateBox(
               var1,
               var5,
               var8 + 1,
               var8,
               var8 + 1,
               this.width - 2 - var8,
               var8,
               this.depth - 2 - var8,
               Blocks.AIR.defaultBlockState(),
               Blocks.AIR.defaultBlockState(),
               false
            );
         }

         for(int var16 = 0; var16 < this.width; ++var16) {
            for(int var9 = 0; var9 < this.depth; ++var9) {
               boolean var10 = true;
               this.fillColumnDown(var1, Blocks.SANDSTONE.defaultBlockState(), var16, -5, var9, var5);
            }
         }

         BlockState var17 = Blocks.SANDSTONE_STAIRS.defaultBlockState().setValue(StairBlock.FACING, Direction.NORTH);
         BlockState var18 = Blocks.SANDSTONE_STAIRS.defaultBlockState().setValue(StairBlock.FACING, Direction.SOUTH);
         BlockState var19 = Blocks.SANDSTONE_STAIRS.defaultBlockState().setValue(StairBlock.FACING, Direction.EAST);
         BlockState var11 = Blocks.SANDSTONE_STAIRS.defaultBlockState().setValue(StairBlock.FACING, Direction.WEST);
         this.generateBox(var1, var5, 0, 0, 0, 4, 9, 4, Blocks.SANDSTONE.defaultBlockState(), Blocks.AIR.defaultBlockState(), false);
         this.generateBox(var1, var5, 1, 10, 1, 3, 10, 3, Blocks.SANDSTONE.defaultBlockState(), Blocks.SANDSTONE.defaultBlockState(), false);
         this.placeBlock(var1, var17, 2, 10, 0, var5);
         this.placeBlock(var1, var18, 2, 10, 4, var5);
         this.placeBlock(var1, var19, 0, 10, 2, var5);
         this.placeBlock(var1, var11, 4, 10, 2, var5);
         this.generateBox(var1, var5, this.width - 5, 0, 0, this.width - 1, 9, 4, Blocks.SANDSTONE.defaultBlockState(), Blocks.AIR.defaultBlockState(), false);
         this.generateBox(
            var1, var5, this.width - 4, 10, 1, this.width - 2, 10, 3, Blocks.SANDSTONE.defaultBlockState(), Blocks.SANDSTONE.defaultBlockState(), false
         );
         this.placeBlock(var1, var17, this.width - 3, 10, 0, var5);
         this.placeBlock(var1, var18, this.width - 3, 10, 4, var5);
         this.placeBlock(var1, var19, this.width - 5, 10, 2, var5);
         this.placeBlock(var1, var11, this.width - 1, 10, 2, var5);
         this.generateBox(var1, var5, 8, 0, 0, 12, 4, 4, Blocks.SANDSTONE.defaultBlockState(), Blocks.AIR.defaultBlockState(), false);
         this.generateBox(var1, var5, 9, 1, 0, 11, 3, 4, Blocks.AIR.defaultBlockState(), Blocks.AIR.defaultBlockState(), false);
         this.placeBlock(var1, Blocks.CUT_SANDSTONE.defaultBlockState(), 9, 1, 1, var5);
         this.placeBlock(var1, Blocks.CUT_SANDSTONE.defaultBlockState(), 9, 2, 1, var5);
         this.placeBlock(var1, Blocks.CUT_SANDSTONE.defaultBlockState(), 9, 3, 1, var5);
         this.placeBlock(var1, Blocks.CUT_SANDSTONE.defaultBlockState(), 10, 3, 1, var5);
         this.placeBlock(var1, Blocks.CUT_SANDSTONE.defaultBlockState(), 11, 3, 1, var5);
         this.placeBlock(var1, Blocks.CUT_SANDSTONE.defaultBlockState(), 11, 2, 1, var5);
         this.placeBlock(var1, Blocks.CUT_SANDSTONE.defaultBlockState(), 11, 1, 1, var5);
         this.generateBox(var1, var5, 4, 1, 1, 8, 3, 3, Blocks.SANDSTONE.defaultBlockState(), Blocks.AIR.defaultBlockState(), false);
         this.generateBox(var1, var5, 4, 1, 2, 8, 2, 2, Blocks.AIR.defaultBlockState(), Blocks.AIR.defaultBlockState(), false);
         this.generateBox(var1, var5, 12, 1, 1, 16, 3, 3, Blocks.SANDSTONE.defaultBlockState(), Blocks.AIR.defaultBlockState(), false);
         this.generateBox(var1, var5, 12, 1, 2, 16, 2, 2, Blocks.AIR.defaultBlockState(), Blocks.AIR.defaultBlockState(), false);
         this.generateBox(
            var1, var5, 5, 4, 5, this.width - 6, 4, this.depth - 6, Blocks.SANDSTONE.defaultBlockState(), Blocks.SANDSTONE.defaultBlockState(), false
         );
         this.generateBox(var1, var5, 9, 4, 9, 11, 4, 11, Blocks.AIR.defaultBlockState(), Blocks.AIR.defaultBlockState(), false);
         this.generateBox(var1, var5, 8, 1, 8, 8, 3, 8, Blocks.CUT_SANDSTONE.defaultBlockState(), Blocks.CUT_SANDSTONE.defaultBlockState(), false);
         this.generateBox(var1, var5, 12, 1, 8, 12, 3, 8, Blocks.CUT_SANDSTONE.defaultBlockState(), Blocks.CUT_SANDSTONE.defaultBlockState(), false);
         this.generateBox(var1, var5, 8, 1, 12, 8, 3, 12, Blocks.CUT_SANDSTONE.defaultBlockState(), Blocks.CUT_SANDSTONE.defaultBlockState(), false);
         this.generateBox(var1, var5, 12, 1, 12, 12, 3, 12, Blocks.CUT_SANDSTONE.defaultBlockState(), Blocks.CUT_SANDSTONE.defaultBlockState(), false);
         this.generateBox(var1, var5, 1, 1, 5, 4, 4, 11, Blocks.SANDSTONE.defaultBlockState(), Blocks.SANDSTONE.defaultBlockState(), false);
         this.generateBox(
            var1, var5, this.width - 5, 1, 5, this.width - 2, 4, 11, Blocks.SANDSTONE.defaultBlockState(), Blocks.SANDSTONE.defaultBlockState(), false
         );
         this.generateBox(var1, var5, 6, 7, 9, 6, 7, 11, Blocks.SANDSTONE.defaultBlockState(), Blocks.SANDSTONE.defaultBlockState(), false);
         this.generateBox(
            var1, var5, this.width - 7, 7, 9, this.width - 7, 7, 11, Blocks.SANDSTONE.defaultBlockState(), Blocks.SANDSTONE.defaultBlockState(), false
         );
         this.generateBox(var1, var5, 5, 5, 9, 5, 7, 11, Blocks.CUT_SANDSTONE.defaultBlockState(), Blocks.CUT_SANDSTONE.defaultBlockState(), false);
         this.generateBox(
            var1, var5, this.width - 6, 5, 9, this.width - 6, 7, 11, Blocks.CUT_SANDSTONE.defaultBlockState(), Blocks.CUT_SANDSTONE.defaultBlockState(), false
         );
         this.placeBlock(var1, Blocks.AIR.defaultBlockState(), 5, 5, 10, var5);
         this.placeBlock(var1, Blocks.AIR.defaultBlockState(), 5, 6, 10, var5);
         this.placeBlock(var1, Blocks.AIR.defaultBlockState(), 6, 6, 10, var5);
         this.placeBlock(var1, Blocks.AIR.defaultBlockState(), this.width - 6, 5, 10, var5);
         this.placeBlock(var1, Blocks.AIR.defaultBlockState(), this.width - 6, 6, 10, var5);
         this.placeBlock(var1, Blocks.AIR.defaultBlockState(), this.width - 7, 6, 10, var5);
         this.generateBox(var1, var5, 2, 4, 4, 2, 6, 4, Blocks.AIR.defaultBlockState(), Blocks.AIR.defaultBlockState(), false);
         this.generateBox(var1, var5, this.width - 3, 4, 4, this.width - 3, 6, 4, Blocks.AIR.defaultBlockState(), Blocks.AIR.defaultBlockState(), false);
         this.placeBlock(var1, var17, 2, 4, 5, var5);
         this.placeBlock(var1, var17, 2, 3, 4, var5);
         this.placeBlock(var1, var17, this.width - 3, 4, 5, var5);
         this.placeBlock(var1, var17, this.width - 3, 3, 4, var5);
         this.generateBox(var1, var5, 1, 1, 3, 2, 2, 3, Blocks.SANDSTONE.defaultBlockState(), Blocks.SANDSTONE.defaultBlockState(), false);
         this.generateBox(
            var1, var5, this.width - 3, 1, 3, this.width - 2, 2, 3, Blocks.SANDSTONE.defaultBlockState(), Blocks.SANDSTONE.defaultBlockState(), false
         );
         this.placeBlock(var1, Blocks.SANDSTONE.defaultBlockState(), 1, 1, 2, var5);
         this.placeBlock(var1, Blocks.SANDSTONE.defaultBlockState(), this.width - 2, 1, 2, var5);
         this.placeBlock(var1, Blocks.SANDSTONE_SLAB.defaultBlockState(), 1, 2, 2, var5);
         this.placeBlock(var1, Blocks.SANDSTONE_SLAB.defaultBlockState(), this.width - 2, 2, 2, var5);
         this.placeBlock(var1, var11, 2, 1, 2, var5);
         this.placeBlock(var1, var19, this.width - 3, 1, 2, var5);
         this.generateBox(var1, var5, 4, 3, 5, 4, 3, 17, Blocks.SANDSTONE.defaultBlockState(), Blocks.SANDSTONE.defaultBlockState(), false);
         this.generateBox(
            var1, var5, this.width - 5, 3, 5, this.width - 5, 3, 17, Blocks.SANDSTONE.defaultBlockState(), Blocks.SANDSTONE.defaultBlockState(), false
         );
         this.generateBox(var1, var5, 3, 1, 5, 4, 2, 16, Blocks.AIR.defaultBlockState(), Blocks.AIR.defaultBlockState(), false);
         this.generateBox(var1, var5, this.width - 6, 1, 5, this.width - 5, 2, 16, Blocks.AIR.defaultBlockState(), Blocks.AIR.defaultBlockState(), false);

         for(int var12 = 5; var12 <= 17; var12 += 2) {
            this.placeBlock(var1, Blocks.CUT_SANDSTONE.defaultBlockState(), 4, 1, var12, var5);
            this.placeBlock(var1, Blocks.CHISELED_SANDSTONE.defaultBlockState(), 4, 2, var12, var5);
            this.placeBlock(var1, Blocks.CUT_SANDSTONE.defaultBlockState(), this.width - 5, 1, var12, var5);
            this.placeBlock(var1, Blocks.CHISELED_SANDSTONE.defaultBlockState(), this.width - 5, 2, var12, var5);
         }

         this.placeBlock(var1, Blocks.ORANGE_TERRACOTTA.defaultBlockState(), 10, 0, 7, var5);
         this.placeBlock(var1, Blocks.ORANGE_TERRACOTTA.defaultBlockState(), 10, 0, 8, var5);
         this.placeBlock(var1, Blocks.ORANGE_TERRACOTTA.defaultBlockState(), 9, 0, 9, var5);
         this.placeBlock(var1, Blocks.ORANGE_TERRACOTTA.defaultBlockState(), 11, 0, 9, var5);
         this.placeBlock(var1, Blocks.ORANGE_TERRACOTTA.defaultBlockState(), 8, 0, 10, var5);
         this.placeBlock(var1, Blocks.ORANGE_TERRACOTTA.defaultBlockState(), 12, 0, 10, var5);
         this.placeBlock(var1, Blocks.ORANGE_TERRACOTTA.defaultBlockState(), 7, 0, 10, var5);
         this.placeBlock(var1, Blocks.ORANGE_TERRACOTTA.defaultBlockState(), 13, 0, 10, var5);
         this.placeBlock(var1, Blocks.ORANGE_TERRACOTTA.defaultBlockState(), 9, 0, 11, var5);
         this.placeBlock(var1, Blocks.ORANGE_TERRACOTTA.defaultBlockState(), 11, 0, 11, var5);
         this.placeBlock(var1, Blocks.ORANGE_TERRACOTTA.defaultBlockState(), 10, 0, 12, var5);
         this.placeBlock(var1, Blocks.ORANGE_TERRACOTTA.defaultBlockState(), 10, 0, 13, var5);
         this.placeBlock(var1, Blocks.BLUE_TERRACOTTA.defaultBlockState(), 10, 0, 10, var5);

         for(int var20 = 0; var20 <= this.width - 1; var20 += this.width - 1) {
            this.placeBlock(var1, Blocks.CUT_SANDSTONE.defaultBlockState(), var20, 2, 1, var5);
            this.placeBlock(var1, Blocks.ORANGE_TERRACOTTA.defaultBlockState(), var20, 2, 2, var5);
            this.placeBlock(var1, Blocks.CUT_SANDSTONE.defaultBlockState(), var20, 2, 3, var5);
            this.placeBlock(var1, Blocks.CUT_SANDSTONE.defaultBlockState(), var20, 3, 1, var5);
            this.placeBlock(var1, Blocks.ORANGE_TERRACOTTA.defaultBlockState(), var20, 3, 2, var5);
            this.placeBlock(var1, Blocks.CUT_SANDSTONE.defaultBlockState(), var20, 3, 3, var5);
            this.placeBlock(var1, Blocks.ORANGE_TERRACOTTA.defaultBlockState(), var20, 4, 1, var5);
            this.placeBlock(var1, Blocks.CHISELED_SANDSTONE.defaultBlockState(), var20, 4, 2, var5);
            this.placeBlock(var1, Blocks.ORANGE_TERRACOTTA.defaultBlockState(), var20, 4, 3, var5);
            this.placeBlock(var1, Blocks.CUT_SANDSTONE.defaultBlockState(), var20, 5, 1, var5);
            this.placeBlock(var1, Blocks.ORANGE_TERRACOTTA.defaultBlockState(), var20, 5, 2, var5);
            this.placeBlock(var1, Blocks.CUT_SANDSTONE.defaultBlockState(), var20, 5, 3, var5);
            this.placeBlock(var1, Blocks.ORANGE_TERRACOTTA.defaultBlockState(), var20, 6, 1, var5);
            this.placeBlock(var1, Blocks.CHISELED_SANDSTONE.defaultBlockState(), var20, 6, 2, var5);
            this.placeBlock(var1, Blocks.ORANGE_TERRACOTTA.defaultBlockState(), var20, 6, 3, var5);
            this.placeBlock(var1, Blocks.ORANGE_TERRACOTTA.defaultBlockState(), var20, 7, 1, var5);
            this.placeBlock(var1, Blocks.ORANGE_TERRACOTTA.defaultBlockState(), var20, 7, 2, var5);
            this.placeBlock(var1, Blocks.ORANGE_TERRACOTTA.defaultBlockState(), var20, 7, 3, var5);
            this.placeBlock(var1, Blocks.CUT_SANDSTONE.defaultBlockState(), var20, 8, 1, var5);
            this.placeBlock(var1, Blocks.CUT_SANDSTONE.defaultBlockState(), var20, 8, 2, var5);
            this.placeBlock(var1, Blocks.CUT_SANDSTONE.defaultBlockState(), var20, 8, 3, var5);
         }

         for(int var21 = 2; var21 <= this.width - 3; var21 += this.width - 3 - 2) {
            this.placeBlock(var1, Blocks.CUT_SANDSTONE.defaultBlockState(), var21 - 1, 2, 0, var5);
            this.placeBlock(var1, Blocks.ORANGE_TERRACOTTA.defaultBlockState(), var21, 2, 0, var5);
            this.placeBlock(var1, Blocks.CUT_SANDSTONE.defaultBlockState(), var21 + 1, 2, 0, var5);
            this.placeBlock(var1, Blocks.CUT_SANDSTONE.defaultBlockState(), var21 - 1, 3, 0, var5);
            this.placeBlock(var1, Blocks.ORANGE_TERRACOTTA.defaultBlockState(), var21, 3, 0, var5);
            this.placeBlock(var1, Blocks.CUT_SANDSTONE.defaultBlockState(), var21 + 1, 3, 0, var5);
            this.placeBlock(var1, Blocks.ORANGE_TERRACOTTA.defaultBlockState(), var21 - 1, 4, 0, var5);
            this.placeBlock(var1, Blocks.CHISELED_SANDSTONE.defaultBlockState(), var21, 4, 0, var5);
            this.placeBlock(var1, Blocks.ORANGE_TERRACOTTA.defaultBlockState(), var21 + 1, 4, 0, var5);
            this.placeBlock(var1, Blocks.CUT_SANDSTONE.defaultBlockState(), var21 - 1, 5, 0, var5);
            this.placeBlock(var1, Blocks.ORANGE_TERRACOTTA.defaultBlockState(), var21, 5, 0, var5);
            this.placeBlock(var1, Blocks.CUT_SANDSTONE.defaultBlockState(), var21 + 1, 5, 0, var5);
            this.placeBlock(var1, Blocks.ORANGE_TERRACOTTA.defaultBlockState(), var21 - 1, 6, 0, var5);
            this.placeBlock(var1, Blocks.CHISELED_SANDSTONE.defaultBlockState(), var21, 6, 0, var5);
            this.placeBlock(var1, Blocks.ORANGE_TERRACOTTA.defaultBlockState(), var21 + 1, 6, 0, var5);
            this.placeBlock(var1, Blocks.ORANGE_TERRACOTTA.defaultBlockState(), var21 - 1, 7, 0, var5);
            this.placeBlock(var1, Blocks.ORANGE_TERRACOTTA.defaultBlockState(), var21, 7, 0, var5);
            this.placeBlock(var1, Blocks.ORANGE_TERRACOTTA.defaultBlockState(), var21 + 1, 7, 0, var5);
            this.placeBlock(var1, Blocks.CUT_SANDSTONE.defaultBlockState(), var21 - 1, 8, 0, var5);
            this.placeBlock(var1, Blocks.CUT_SANDSTONE.defaultBlockState(), var21, 8, 0, var5);
            this.placeBlock(var1, Blocks.CUT_SANDSTONE.defaultBlockState(), var21 + 1, 8, 0, var5);
         }

         this.generateBox(var1, var5, 8, 4, 0, 12, 6, 0, Blocks.CUT_SANDSTONE.defaultBlockState(), Blocks.CUT_SANDSTONE.defaultBlockState(), false);
         this.placeBlock(var1, Blocks.AIR.defaultBlockState(), 8, 6, 0, var5);
         this.placeBlock(var1, Blocks.AIR.defaultBlockState(), 12, 6, 0, var5);
         this.placeBlock(var1, Blocks.ORANGE_TERRACOTTA.defaultBlockState(), 9, 5, 0, var5);
         this.placeBlock(var1, Blocks.CHISELED_SANDSTONE.defaultBlockState(), 10, 5, 0, var5);
         this.placeBlock(var1, Blocks.ORANGE_TERRACOTTA.defaultBlockState(), 11, 5, 0, var5);
         this.generateBox(var1, var5, 8, -14, 8, 12, -11, 12, Blocks.CUT_SANDSTONE.defaultBlockState(), Blocks.CUT_SANDSTONE.defaultBlockState(), false);
         this.generateBox(
            var1, var5, 8, -10, 8, 12, -10, 12, Blocks.CHISELED_SANDSTONE.defaultBlockState(), Blocks.CHISELED_SANDSTONE.defaultBlockState(), false
         );
         this.generateBox(var1, var5, 8, -9, 8, 12, -9, 12, Blocks.CUT_SANDSTONE.defaultBlockState(), Blocks.CUT_SANDSTONE.defaultBlockState(), false);
         this.generateBox(var1, var5, 8, -8, 8, 12, -1, 12, Blocks.SANDSTONE.defaultBlockState(), Blocks.SANDSTONE.defaultBlockState(), false);
         this.generateBox(var1, var5, 9, -11, 9, 11, -1, 11, Blocks.AIR.defaultBlockState(), Blocks.AIR.defaultBlockState(), false);
         this.placeBlock(var1, Blocks.STONE_PRESSURE_PLATE.defaultBlockState(), 10, -11, 10, var5);
         this.generateBox(var1, var5, 9, -13, 9, 11, -13, 11, Blocks.TNT.defaultBlockState(), Blocks.AIR.defaultBlockState(), false);
         this.placeBlock(var1, Blocks.AIR.defaultBlockState(), 8, -11, 10, var5);
         this.placeBlock(var1, Blocks.AIR.defaultBlockState(), 8, -10, 10, var5);
         this.placeBlock(var1, Blocks.CHISELED_SANDSTONE.defaultBlockState(), 7, -10, 10, var5);
         this.placeBlock(var1, Blocks.CUT_SANDSTONE.defaultBlockState(), 7, -11, 10, var5);
         this.placeBlock(var1, Blocks.AIR.defaultBlockState(), 12, -11, 10, var5);
         this.placeBlock(var1, Blocks.AIR.defaultBlockState(), 12, -10, 10, var5);
         this.placeBlock(var1, Blocks.CHISELED_SANDSTONE.defaultBlockState(), 13, -10, 10, var5);
         this.placeBlock(var1, Blocks.CUT_SANDSTONE.defaultBlockState(), 13, -11, 10, var5);
         this.placeBlock(var1, Blocks.AIR.defaultBlockState(), 10, -11, 8, var5);
         this.placeBlock(var1, Blocks.AIR.defaultBlockState(), 10, -10, 8, var5);
         this.placeBlock(var1, Blocks.CHISELED_SANDSTONE.defaultBlockState(), 10, -10, 7, var5);
         this.placeBlock(var1, Blocks.CUT_SANDSTONE.defaultBlockState(), 10, -11, 7, var5);
         this.placeBlock(var1, Blocks.AIR.defaultBlockState(), 10, -11, 12, var5);
         this.placeBlock(var1, Blocks.AIR.defaultBlockState(), 10, -10, 12, var5);
         this.placeBlock(var1, Blocks.CHISELED_SANDSTONE.defaultBlockState(), 10, -10, 13, var5);
         this.placeBlock(var1, Blocks.CUT_SANDSTONE.defaultBlockState(), 10, -11, 13, var5);

         for(Direction var13 : Direction.Plane.HORIZONTAL) {
            if (!this.hasPlacedChest[var13.get2DDataValue()]) {
               int var14 = var13.getStepX() * 2;
               int var15 = var13.getStepZ() * 2;
               this.hasPlacedChest[var13.get2DDataValue()] = this.createChest(var1, var5, var4, 10 + var14, -11, 10 + var15, BuiltInLootTables.DESERT_PYRAMID);
            }
         }
      }
   }
}
